Workbook

Sheet Accueil
B2: 🦌 PÂTÉ 2026 — Tableau de bord
B3: Journée pâtés de gibier — Maninghem
B4: Légende : 🔵 bleu = à remplir vous-même 🟢 vert = repris d'une autre feuille ⚫ noir = calcul automatique (ne pas toucher)
B6: Gibier net total (kg) | E6: Poids total pâté (kg) | H6: Participants
B7: ='Stocks Gibier'!N26 -> 65.6341 | E7: =SUM(Production!D63:M63) -> 108.28658 | H7: =Paramètres!C7 -> 7
B10: Budget ingrédients (€) | E10: Coût / participant (€) | H10: Bocaux 315g suggérés
B11: ='Budget & Comptes'!C5 -> 345.772 | E11: ='Budget & Comptes'!C7 -> 49.396001 | H11: =SUM(Production!K68:K77) -> 343
B15: RÉCAP PAR PÂTÉ
B16: Pâté | C16: Poids (kg) | D16: Coût (€)
B17: =Production!D5 -> Pâté de lièvre | C17: =Production!D63 -> 10.482749 | D17: ='Budget & Comptes'!C11 -> 26.130738
B18: =Production!E5 -> Pâté de chevreuil | C18: =Production!E63 -> 25.610579 | D18: ='Budget & Comptes'!C12 -> 73.239026
B19: =Production!F5 -> Pâté de sanglier (campagne) | C19: =Production!F63 -> 0 | D19: ='Budget & Comptes'!C13 -> 0
B20: =Production!G5 -> Pâté de faisan | C20: =Production!G63 -> 22.188944 | D20: ='Budget & Comptes'!C14 -> 101.81729
B21: =Production!H5 -> Daube de sanglier | C21: =Production!H63 -> 0 | D21: ='Budget & Comptes'!C15 -> 0
B22: =Production!I5 -> Pâté de foie de sanglier | C22: =Production!I63 -> 27.760385 | D22: ='Budget & Comptes'!C16 -> 49.62578
B23: =Production!J5 -> Pâté de foie de chevreuil | C23: =Production!J63 -> 0 | D23: ='Budget & Comptes'!C17 -> 0
B24: =Production!K5 -> Rillette de perdreaux | C24: =Production!K63 -> 0 | D24: ='Budget & Comptes'!C18 -> 0
B25: =Production!L5 -> Rillette de lièvre | C25: =Production!L63 -> 0 | D25: ='Budget & Comptes'!C19 -> 0
B26: =Production!M5 -> Civet de chevreuil | C26: =Production!M63 -> 22.243924 | D26: ='Budget & Comptes'!C20 -> 94.959175
B27: TOTAL | C27: =SUM(C17:C26) -> 108.28658 | D27: =SUM(D17:D26) -> 345.772
B29: ℹ️ COMMENT UTILISER CE CLASSEUR (dans l'ordre des onglets)
B30: 1. Paramètres — vérifiez les prix des ingrédients et le nombre de participants (cases bleues).
B31: 2. Stocks Gibier — saisissez le gibier apporté par chaque chasseur (cases bleues). Le net se calcule tout seul.
B32: 3. Recettes — les doses par kg de viande. À ne modifier que si vous changez une recette.
B33: 4. Production — tout est automatique : quantités d'ingrédients et poids par pâté. Saisissez le nombre de bocaux par format.
B34: 5. Liste de courses — se remplit seule. Indiquez ce que vous avez « en stock » et qui s'occupe des achats.
B35: 6. Budget & Comptes — coût estimé + comptes réels de la journée et remboursements.
B36: Astuce : les cellules avec un petit triangle rouge contiennent une explication (passez la souris dessus).

Sheet Paramètres
B2: PARAMÈTRES — pâté 2026
B3: Légende : 🔵 bleu = à remplir vous-même ⚫ noir = calcul automatique. Survolez les cellules avec un triangle rouge pour une explication.
B4: GÉNÉRAL
B5: Lieu | C5: VINCENT (Maninghem)
B6: Année | C6: 2026
B7: Nombre de participants | C7: 7
B9: PRIX DES INGRÉDIENTS | G9: FORMATS DE BOCAUX
B10: Ingrédient | C10: Unité | D10: Prix unitaire (€) | E10: Catégorie | G10: Format (g) | H10: Poids réel (g) | I10: Poids réel (kg)
B11: lièvre | C11: kg | E11: Gibier | G11: 125 | H11: 110 | I11: =H11/1000 -> 0.11
B12: chevreuil paté | C12: kg | E12: Gibier | G12: 200 | H12: 180 | I12: =H12/1000 -> 0.18
B13: foie de chevreuil integere dans chevreurol | C13: kg | E13: Gibier | G13: 350 | H13: 315 | I13: =H13/1000 -> 0.315
B14: sanglier | C14: kg | E14: Gibier | G14: 500 | H14: 450 | I14: =H14/1000 -> 0.45
B15: foie de sanglier | C15: kg | E15: Gibier | G15: 750 | H15: 675 | I15: =H15/1000 -> 0.675
B16: foie chevreuil a integrer dans paté capagne | C16: kg | E16: Gibier | G16: 1000 | H16: 900 | I16: =H16/1000 -> 0.9
B17: faisan | C17: kg | E17: Gibier | G17: 1500 | H17: 1350 | I17: =H17/1000 -> 1.35
B18: canard | C18: kg | E18: Gibier
B19: lapin | C19: kg | E19: Gibier
B20: bécasse | C20: kg | E20: Gibier
B21: perdreaux | C21: kg | E21: Gibier
B22: chevreiil civet | C22: kg | E22: Gibier
B23: gorge de porc | C23: kg | D23: 3.2 | E23: Achat
B24: ECHINE DE PORC | C24: kg | D24: 8 | E24: Achat
B25: lard GRAS | C25: kg | D25: 12 | E25: Achat
B26: poitrine de porc | C26: kg | D26: 8 | E26: Achat
B27: poitrine fumée | C27: kg | D27: 12.5 | E27: Achat
B28: chair à saucisse | C28: kg | D28: 10 | E28: Achat
B29: barde | C29: m2 | D29: 20 | E29: Achat
B30: VEAU poitrine | C30: kg | D30: 16 | E30: Achat
B31: foie de volailles | C31: kg | D31: 15 | E31: Achat
B32: saindoux | C32: kg | D32: 6 | E32: Achat
B33: sel | C33: kg | D33: 1.2 | E33: Achat
B34: poivre | C34: kg | D34: 30 | E34: Achat
... B43: carottes nouvelles | C43: kg | D43: 3.5 | E43: Achat
B44: gingembre | C44: CC | E44: Achat
B45: baies genievre | E45: Achat
B46: PISTACHES | C46: KG | D46: 30 | E46: Achat
B47: celeri branche | C47: br | D47: 0.5 | E47: Achat
B48: champignons | C48: kg | D48: 3 | E48: Achat
B49: tomates | C49: kg | D49: 4.5 | E49: Achat
B50: olives noires niçoises | C50: kg | D50: 20 | E50: Achat
...

Sheet Stocks Gibier
B2: STOCKS GIBIER — apports par chasseur
B3: Légende : 🔵 bleu = à remplir vous-même ⚫ noir = calcul automatique. Survolez les triangles rouges pour une explication.
B4: Saisissez les apports (kg) de chaque chasseur. Brut et Net se calculent automatiquement.
B6: Type de gibier | C6: vincent | D6: denis | E6: thomas D | F6: benoit | G6: JB | H6: françois | I6: olivier | J6: antoine | K6: frederic | L6: Total brut (kg) | M6: Rendement | N6: Net (kg)
B7: lievre avec os | C7: 4.33 | D7: 4.45 | G7: 1.8 | L7: =SUM(C7:K7) -> 10.58 | M7: 0.56 | N7: =L7*M7 -> 5.9248
B8: lièvre sans os | L8: =SUM(C8:K8) -> 0 | M8: 1 | N8: =L8*M8 -> 0
B9: lièvre pour rillette | L9: =SUM(C9:K9) -> 0 | M9: 1 | N9: =L9*M9 -> 0
B10: chevreuil epaule/ gigue entières | C10: 2.63 | D10: 4.53 | I10: 3.53 | K10: 1.78 | L10: =SUM(C10:K10) -> 12.47 | M10: 0.65 | N10: =L10*M10 -> 8.1055
B11: chevreuil chair | C11: 5.3 | D11: 2.71 | G11: 2.9 | I11: 0.973 | K11: 1.4 | L11: =SUM(C11:K11) -> 13.283 | M11: 1 | N11: =L11*M11 -> 13.283
B12: foie et abats chevreuil | C12: 0.67 | G12: 0.7 | L12: =SUM(C12:K12) -> 1.37 | M12: 0.9 | N12: =L12*M12 -> 1.233
B13: foie chevreuil pour paté campagne | D13: 2.6 | K13: 2.9 | L13: =SUM(C13:K13) -> 5.5 | M13: 0.9 | N13: =L13*M13 -> 4.95
B14: sanglier avec os | C14: 2.9 | D14: 4.8 | K14: 5.6 | L14: =SUM(C14:K14) -> 13.3 | M14: 0.95 | N14: =L14*M14 -> 12.635
B15: sanglier chair | L15: =SUM(C15:K15) -> 0 | M15: 1 | N15: =L15*M15 -> 0
B16: sanglier foie | K16: 2 | L16: =SUM(C16:K16) -> 2 | M16: 1 | N16: =L16*M16 -> 2
B17: cerf avec os | L17: =SUM(C17:K17) -> 0 | M17: 0.8 | N17: =L17*M17 -> 0
B18: cerf chair | L18: =SUM(C18:K18) -> 0 | M18: 1 | N18: =L18*M18 -> 0
B19: faisan avec os | C19: 1.9 | D19: 3.84 | G19: 5.8 | I19: 0.95 | K19: 12.4 | L19: =SUM(C19:K19) -> 24.89 | M19: 0.52 | N19: =L19*M19 -> 12.9428
B20: faisan sans os | G20: 0.8 | L20: =SUM(C20:K20) -> 0.8 | M20: 0.95 | N20: =L20*M20 -> 0.76
B21: canard | L21: =SUM(C21:K21) -> 0 | M21: 0.6 | N21: =L21*M21 -> 0
B22: lapin avec os | L22: =SUM(C22:K22) -> 0 | M22: 0.6 | N22: =L22*M22 -> 0
B23: lapin sans os | L23: =SUM(C23:K23) -> 0 | M23: 1 | N23: =L23*M23 -> 0
B24: bécasse 250 gr pièce | D24: 1.25 | G24: 2.5 | I24: 0.75 | K24: 1.5 | L24: =SUM(C24:K24) -> 6 | M24: 0.5 | N24: =L24*M24 -> 3
B25: perdrix pigeon entier | G25: 1.6 | L25: =SUM(C25:K25) -> 1.6 | M25: 0.5 | N25: =L25*M25 -> 0.8
B26: TOTAL | C26: =SUM(C7:C25) -> 17.73 | D26: =SUM(D7:D25) -> 24.18 | E26: =SUM(E7:E25) -> 0 | F26: =SUM(F7:F25) -> 0 | G26: =SUM(G7:G25) -> 16.1 | H26: =SUM(H7:H25) -> 0 | I26: =SUM(I7:I25) -> 6.203 | J26: =SUM(J7:J25) -> 0 | ... L26: =SUM(L7:L25) -> 91.793 | N26: =SUM(N7:N25) -> 65.6341

Sheet Recettes
B2: RECETTES — quantité d'ingrédient par kg de viande de base | O2: ▼ Choisir une recette : | P2: Pâté de sanglier (campagne)
B3: Légende : 🔵 bleu = dose modifiable ⚫ noir = calcul. Choisissez une recette dans la liste déroulante à droite (cellule jaune).
B4: Coefficients : pour 1 kg de viande, combien d'ingrédient. (bleu = modifiable)
B6: Ingrédient | C6: Unité | D6: Pâté de lièvre | E6: Pâté de chevreuil | F6: Pâté de sanglier (campagne) | G6: Pâté de faisan | H6: Daube de sanglier | I6: Pâté de foie de sanglier | J6: Pâté de foie de chevreuil | K6: Rillette de perdreaux | L6: Rillette de lièvre | M6: Civet de chevreuil | O6: Sélection (qté/kg)
B7: lièvre | C7: kg | D7: 1 | L7: 1 | O7: =IFERROR(INDEX($D7:$M7,MATCH($P$2,$D$6:$M$6,0)),"") -> 0
B8: chevreuil paté | C8: kg | E8: 1 | O8: =IFERROR(INDEX($D8:$M8,MATCH($P$2,$D$6:$M$6,0)),"") -> 0
B9: foie de chevreuil integere dans chevreurol | C9: kg | I9: 1.8 | J9: 1 | O9: =IFERROR(INDEX($D9:$M9,MATCH($P$2,$D$6:$M$6,0)),"") -> 0
B10: sanglier | C10: kg | F10: 0 | H10: 1 | O10: =IFERROR(INDEX($D10:$M10,MATCH($P$2,$D$6:$M$6,0)),"") -> 0
B11: foie de sanglier | C11: kg | F11: 1 | I11: 1 | O11: =IFERROR(INDEX($D11:$M11,MATCH($P$2,$D$6:$M$6,0)),"") -> 1
B12: foie chevreuil a integrer dans paté capagne | C12: kg | O12: =IFERROR(INDEX($D12:$M12,MATCH($P$2,$D$6:$M$6,0)),"") -> 0
B13: faisan | C13: kg | G13: 1 | O13: =IFERROR(INDEX($D13:$M13,MATCH($P$2,$D$6:$M$6,0)),"") -> 0
B14: canard | C14: kg | O14: =IFERROR(INDEX($D14:$M14,MATCH($P$2,$D$6:$M$6,0)),"") -> 0
B15: lapin | C15: kg | O15: =IFERROR(INDEX($D15:$M15,MATCH($P$2,$D$6:$M$6,0)),"") -> 0
B16: bécasse | C16: kg | O16: =IFERROR(INDEX($D16:$M16,MATCH($P$2,$D$6:$M$6,0)),"") -> 0
B17: perdreaux | C17: kg | K17: 1 | O17: =IFERROR(INDEX($D17:$M17,MATCH($P$2,$D$6:$M$6,0)),"") -> 0
B18: chevreiil civet | C18: kg | M18: 1 | O18: =IFERROR(INDEX($D18:$M18,MATCH($P$2,$D$6:$M$6,0)),"") -> 0
B19: gorge de porc | C19: kg | D19: 0.6 | E19: 0.6 | F19: 1 | G19: 0.2 | I19: 1 | J19: 0.8 | L19: 0.5 | O19: =IFERROR(INDEX($D19:$M19,MATCH($P$2,$D$6:$M$6,0)),"") -> 1
B20: ECHINE DE PORC | C20: kg | H20: 0.2 | I20: 0 | J20: 1.5 | O20: =IFERROR(INDEX($D20:$M20,MATCH($P$2,$D$6:$M$6,0)),"") -> 0
B21: lard GRAS | C21: kg | O21: =IFERROR(INDEX($D21:$M21,MATCH($P$2,$D$6:$M$6,0)),"") -> 0
B22: poitrine de porc | C22: kg | K22: 0.65 | M22: 0.4 | O22: =IFERROR(INDEX($D22:$M22,MATCH($P$2,$D$6:$M$6,0)),"") -> 0
B23: poitrine fumée | C23: kg | O23: =IFERROR(INDEX($D23:$M23,MATCH($P$2,$D$6:$M$6,0)),"") -> 0
B24: chair à saucisse | C24: kg | O24: =IFERROR(INDEX($D24:$M24,MATCH($P$2,$D$6:$M$6,0)),"") -> 0
B25: barde | C25: m2 | O25: =IFERROR(INDEX($D25:$M25,MATCH($P$2,$D$6:$M$6,0)),"") -> 0
B26: VEAU poitrine | C26: kg | G26: 0.25 | O26: =IFERROR(INDEX($D26:$M26,MATCH($P$2,$D$6:$M$6,0)),"") -> 0
B27: foie de volailles | C27: kg | O27: =IFERROR(INDEX($D27:$M27,MATCH($P$2,$D$6:$M$6,0)),"") -> 0
B28: saindoux | C28: kg | K28: 0.5 | L28: 0.35 | O28: =IFERROR(INDEX($D28:$M28,MATCH($P$2,$D$6:$M$6,0)),"") -> 0
B29: sel | C29: kg | D29: 0.012 | E29: 0.012 | F29: 0.013 | G29: 0.012 | H29: 0.012 | I29: 0.012 | J29: 0.012 | K29: 0.012 | L29: 0.012 | M29: 0.012 | O29: =IFERROR(INDEX($D29:$M29,MATCH($P$2,$D$6:$M$6,0)),"") -> 0.013
B30: poivre | C30: kg | D30: 0.002 | E30: 0.002 | F30: 0.002 | G30: 0.002 | H30: 0.002 | I30: 0.002 | J30: 0.002 | K30: 0.002 | L30: 0.002 | M30: 0.002 | O30: =IFERROR(INDEX($D30:$M30,MATCH($P$2,$D$6:$M$6,0)),"") -> 0.002
B31: sucre | C31: kg | D31: 0.005 | E31: 0.005 | F31: 0.005 | G31: 0.005 | I31: 0.005 | J31: 0.005 | K31: 0.005 | O31: =IFERROR(INDEX($D31:$M31,MATCH($P$2,$D$6:$M$6,0)),"") -> 0.005
B32: 4 épices | C32: g | D32: 0.3 | E32: 0.3 | F32: 1 | G32: 0.3 | I32: 0.3 | J32: 1 | K32: 1 | L32: 1 | M32: 0.3 | O32: =IFERROR(INDEX($D32:$M32,MATCH($P$2,$D$6:$M$6,0)),"") -> 1
B33: poivre vert | C33: g | F33: 5 | I33: 5 | O33: =IFERROR(INDEX($D33:$M33,MATCH($P$2,$D$6:$M$6,0)),"") -> 5
B34: clous de girofle | C34: u | H34: 3 | O34: =IFERROR(INDEX($D34:$M34,MATCH($P$2,$D$6:$M$6,0)),"") -> 0
B35: huile d'olive | C35: l | H35: 0.1 | M35: 0.01 | O35: =IFERROR(INDEX($D35:$M35,MATCH($P$2,$D$6:$M$6,0)),"") -> 0
B36: vinaigre de vin | C36: l | O36: =IFERROR(INDEX($D36:$M36,MATCH($P$2,$D$6:$M$6,0)),"") -> 0
B37: cacao vanhouten | C37: CS | E37: 0.5 | O37: =IFERROR(INDEX($D37:$M37,MATCH($P$2,$D$6:$M$6,0)),"") -> 0
B38: carottes pour bocaux | C38: u | D38: 0.5 | E38: 0.5 | F38: 0.5 | G38: 0.5 | I38: 0.5 | J38: 0.5 | O38: =IFERROR(INDEX($D38:$M38,MATCH($P$2,$D$6:$M$6,0)),"") -> 0.5
B39: carottes nouvelles | C39: kg | H39: 1 | K39: 0.1 | L39: 0.15 | M39: 0.75 | O39: =IFERROR(INDEX($D39:$M39,MATCH($P$2,$D$6:$M$6,0)),"") -> 0
B40: gingembre | C40: CC | F40: 1 | O40: =IFERROR(INDEX($D40:$M40,MATCH($P$2,$D$6:$M$6,0)),"") -> 1
B41: baies genievre | K41: 1 | O41: =IFERROR(INDEX($D41:$M41,MATCH($P$2,$D$6:$M$6,0)),"") -> 0
B42: PISTACHES | C42: KG | G42: 0 | O42: =IFERROR(INDEX($D42:$M42,MATCH($P$2,$D$6:$M$6,0)),"") -> 0
...

Sheet Production
B2: PRODUCTION — quantités calculées automatiquement
B3: Légende : 🔵 bleu = à remplir (bocaux) 🟢 vert = repris d'une autre feuille ⚫ noir = calcul automatique. Survolez les triangles rouges pour l'aide.
B4: VIANDE DE BASE PAR PÂTÉ (kg net)
D5: Pâté de lièvre | E5: Pâté de chevreuil | F5: Pâté de sanglier (campagne) | G5: Pâté de faisan | H5: Daube de sanglier | I5: Pâté de foie de sanglier | J5: Pâté de foie de chevreuil | K5: Rillette de perdreaux | L5: Rillette de lièvre | M5: Civet de chevreuil
B6: Viande de base (kg) | D6: ='Stocks Gibier'!N7+'Stocks Gibier'!N8 -> 5.9248 | E6: ='Stocks Gibier'!N11+'Stocks Gibier'!N12 -> 14.516 | F6: ='Stocks Gibier'!N15 -> 0 | G6: ='Stocks Gibier'!N19+'Stocks Gibier'!N20 -> 13.7028 | H6: =0 -> 0 | I6: ='Stocks Gibier'!N16+'Stocks Gibier'!N13 -> 6.95 | J6: =0 -> 0 | K6: =0 -> 0 | L6: ='Stocks Gibier'!N9 -> 0 | M6: ='Stocks Gibier'!N10 -> 8.1055
B7: Tout ce tableau se calcule automatiquement à partir des Recettes et de la viande de base (ligne 6). Rien à saisir ici.
B8: Ingrédient | C8: Unité | D8: =D$5 -> Pâté de lièvre | E8: =E$5 -> Pâté de chevreuil | F8: =F$5 -> Pâté de sanglier (campagne) | G8: =G$5 -> Pâté de faisan | H8: =H$5 -> Daube de sanglier | I8: =I$5 -> Pâté de foie de sanglier | J8: =J$5 -> Pâté de foie de chevreuil | K8: =K$5 -> Rillette de perdreaux | ... M8: =M$5 -> Civet de chevreuil | N8: Total qté | O8: f.coût | P8: fact. masse (kg)
B9: =Recettes!B7 -> lièvre | C9: =Recettes!C7 -> kg | D9: =Recettes!D7*D$6 -> 5.9248 | E9: =Recettes!E7*E$6 -> 0 | F9: =Recettes!F7*F$6 -> 0 | G9: =Recettes!G7*G$6 -> 0 | H9: =Recettes!H7*H$6 -> 0 | I9: =Recettes!I7*I$6 -> 0 | J9: =Recettes!J7*J$6 -> 0 | K9: =Recettes!K7*K$6 -> 0 | ... M9: =Recettes!M7*M$6 -> 0 | N9: =SUM(D9:M9) -> 5.9248 | O9: =IF(C9="g",0.001,1) -> 1 | P9: =IF(OR(C9="kg",C9="KG",C9="l"),1,IF(C9="g",0.001,0)) -> 1
B10: =Recettes!B8 -> chevreuil paté | C10: =Recettes!C8 -> kg | D10: =Recettes!D8*D$6 -> 0 | E10: =Recettes!E8*E$6 -> 14.516 | F10: =Recettes!F8*F$6 -> 0 | G10: =Recettes!G8*G$6 -> 0 | H10: =Recettes!H8*H$6 -> 0 | I10: =Recettes!I8*I$6 -> 0 | J10: =Recettes!J8*J$6 -> 0 | K10: =Recettes!K8*K$6 -> 0 | ... M10: =Recettes!M8*M$6 -> 0 | N10: =SUM(D10:M10) -> 14.516 | O10: =IF(C10="g",0.001,1) -> 1 | P10: =IF(OR(C10="kg",C10="KG",C10="l"),1,IF(C10="g",0.001,0)) -> 1
B11: =Recettes!B9 -> foie de chevreuil integere dans chevreurol | C11: =Recettes!C9 -> kg | D11: =Recettes!D9*D$6 -> 0 | E11: =Recettes!E9*E$6 -> 0 | F11: =Recettes!F9*F$6 -> 0 | G11: =Recettes!G9*G$6 -> 0 | H11: =Recettes!H9*H$6 -> 0 | I11: =Recettes!I9*I$6 -> 12.51 | J11: =Recettes!J9*J$6 -> 0 | K11: =Recettes!K9*K$6 -> 0 | ... M11: =Recettes!M9*M$6 -> 0 | N11: =SUM(D11:M11) -> 12.51 | O11: =IF(C11="g",0.001,1) -> 1 | P11: =IF(OR(C11="kg",C11="KG",C11="l"),1,IF(C11="g",0.001,0)) -> 1
B12: =Recettes!B10 -> sanglier | C12: =Recettes!C10 -> kg | D12: =Recettes!D10*D$6 -> 0 | E12: =Recettes!E10*E$6 -> 0 | F12: =Recettes!F10*F$6 -> 0 | G12: =Recettes!G10*G$6 -> 0 | H12: =Recettes!H10*H$6 -> 0 | I12: =Recettes!I10*I$6 -> 0 | J12: =Recettes!J10*J$6 -> 0 | K12: =Recettes!K10*K$6 -> 0 | ... M12: =Recettes!M10*M$6 -> 0 | N12: =SUM(D12:M12) -> 0 | O12: =IF(C12="g",0.001,1) -> 1 | P12: =IF(OR(C12="kg",C12="KG",C12="l"),1,IF(C12="g",0.001,0)) -> 1
B13: =Recettes!B11 -> foie de sanglier | C13: =Recettes!C11 -> kg | D13: =Recettes!D11*D$6 -> 0 | E13: =Recettes!E11*E$6 -> 0 | F13: =Recettes!F11*F$6 -> 0 | G13: =Recettes!G11*G$6 -> 0 | H13: =Recettes!H11*H$6 -> 0 | I13: =Recettes!I11*I$6 -> 6.95 | J13: =Recettes!J11*J$6 -> 0 | K13: =Recettes!K11*K$6 -> 0 | ... M13: =Recettes!M11*M$6 -> 0 | N13: =SUM(D13:M13) -> 6.95 | O13: =IF(C13="g",0.001,1) -> 1 | P13: =IF(OR(C13="kg",C13="KG",C13="l"),1,IF(C13="g",0.001,0)) -> 1
B14: =Recettes!B12 -> foie chevreuil a integrer dans paté capagne | C14: =Recettes!C12 -> kg | D14: =Recettes!D12*D$6 -> 0 | E14: =Recettes!E12*E$6 -> 0 | F14: =Recettes!F12*F$6 -> 0 | G14: =Recettes!G12*G$6 -> 0 | H14: =Recettes!H12*H$6 -> 0 | I14: =Recettes!I12*I$6 -> 0 | J14: =Recettes!J12*J$6 -> 0 | K14: =Recettes!K12*K$6 -> 0 | ... M14: =Recettes!M12*M$6 -> 0 | N14: =SUM(D14:M14) -> 0 | O14: =IF(C14="g",0.001,1) -> 1 | P14: =IF(OR(C14="kg",C14="KG",C14="l"),1,IF(C14="g",0.001,0)) -> 1
B15: =Recettes!B13 -> faisan | C15: =Recettes!C13 -> kg | D15: =Recettes!D13*D$6 -> 0 | E15: =Recettes!E13*E$6 -> 0 | F15: =Recettes!F13*F$6 -> 0 | G15: =Recettes!G13*G$6 -> 13.7028 | H15: =Recettes!H13*H$6 -> 0 | I15: =Recettes!I13*I$6 -> 0 | J15: =Recettes!J13*J$6 -> 0 | K15: =Recettes!K13*K$6 -> 0 | ... M15: =Recettes!M13*M$6 -> 0 | N15: =SUM(D15:M15) -> 13.7028 | O15: =IF(C15="g",0.001,1) -> 1 | P15: =IF(OR(C15="kg",C15="KG",C15="l"),1,IF(C15="g",0.001,0)) -> 1
B16: =Recettes!B14 -> canard | C16: =Recettes!C14 -> kg | D16: =Recettes!D14*D$6 -> 0 | E16: =Recettes!E14*E$6 -> 0 | F16: =Recettes!F14*F$6 -> 0 | G16: =Recettes!G14*G$6 -> 0 | H16: =Recettes!H14*H$6 -> 0 | I16: =Recettes!I14*I$6 -> 0 | J16: =Recettes!J14*J$6 -> 0 | K16: =Recettes!K14*K$6 -> 0 | ... M16: =Recettes!M14*M$6 -> 0 | N16: =SUM(D16:M16) -> 0 | O16: =IF(C16="g",0.001,1) -> 1 | P16: =IF(OR(C16="kg",C16="KG",C16="l"),1,IF(C16="g",0.001,0)) -> 1
B17: =Recettes!B15 -> lapin | C17: =Recettes!C15 -> kg | D17: =Recettes!D15*D$6 -> 0 | E17: =Recettes!E15*E$6 -> 0 | F17: =Recettes!F15*F$6 -> 0 | G17: =Recettes!G15*G$6 -> 0 | H17: =Recettes!H15*H$6 -> 0 | I17: =Recettes!I15*I$6 -> 0 | J17: =Recettes!J15*J$6 -> 0 | K17: =Recettes!K15*K$6 -> 0 | ... M17: =Recettes!M15*M$6 -> 0 | N17: =SUM(D17:M17) -> 0 | O17: =IF(C17="g",0.001,1) -> 1 | P17: =IF(OR(C17="kg",C17="KG",C17="l"),1,IF(C17="g",0.001,0)) -> 1
B18: =Recettes!B16 -> bécasse | C18: =Recettes!C16 -> kg | D18: =Recettes!D16*D$6 -> 0 | E18: =Recettes!E16*E$6 -> 0 | F18: =Recettes!F16*F$6 -> 0 | G18: =Recettes!G16*G$6 -> 0 | H18: =Recettes!H16*H$6 -> 0 | I18: =Recettes!I16*I$6 -> 0 | J18: =Recettes!J16*J$6 -> 0 | K18: =Recettes!K16*K$6 -> 0 | ... M18: =Recettes!M16*M$6 -> 0 | N18: =SUM(D18:M18) -> 0 | O18: =IF(C18="g",0.001,1) -> 1 | P18: =IF(OR(C18="kg",C18="KG",C18="l"),1,IF(C18="g",0.001,0)) -> 1
B19: =Recettes!B17 -> perdreaux | C19: =Recettes!C17 -> kg | D19: =Recettes!D17*D$6 -> 0 | E19: =Recettes!E17*E$6 -> 0 | F19: =Recettes!F17*F$6 -> 0 | G19: =Recettes!G17*G$6 -> 0 | H19: =Recettes!H17*H$6 -> 0 | I19: =Recettes!I17*I$6 -> 0 | J19: =Recettes!J17*J$6 -> 0 | K19: =Recettes!K17*K$6 -> 0 | ... M19: =Recettes!M17*M$6 -> 0 | N19: =SUM(D19:M19) -> 0 | O19: =IF(C19="g",0.001,1) -> 1 | P19: =IF(OR(C19="kg",C19="KG",C19="l"),1,IF(C19="g",0.001,0)) -> 1
B20: =Recettes!B18 -> chevreiil civet | C20: =Recettes!C18 -> kg | D20: =Recettes!D18*D$6 -> 0 | E20: =Recettes!E18*E$6 -> 0 | F20: =Recettes!F18*F$6 -> 0 | G20: =Recettes!G18*G$6 -> 0 | H20: =Recettes!H18*H$6 -> 0 | I20: =Recettes!I18*I$6 -> 0 | J20: =Recettes!J18*J$6 -> 0 | K20: =Recettes!K18*K$6 -> 0 | ... M20: =Recettes!M18*M$6 -> 8.1055 | N20: =SUM(D20:M20) -> 8.1055 | O20: =IF(C20="g",0.001,1) -> 1 | P20: =IF(OR(C20="kg",C20="KG",C20="l"),1,IF(C20="g",0.001,0)) -> 1
... B62: =Recettes!B60 -> porto | C62: =Recettes!C60 -> l | D62: =Recettes!D60*D$6 -> 0 | E62: =Recettes!E60*E$6 -> 0.65322 | F62: =Recettes!F60*F$6 -> 0 | G62: =Recettes!G60*G$6 -> 0 | H62: =Recettes!H60*H$6 -> 0 | I62: =Recettes!I60*I$6 -> 0 | J62: =Recettes!J60*J$6 -> 0 | K62: =Recettes!K60*K$6 -> 0 | ... M62: =Recettes!M60*M$6 -> 0 | N62: =SUM(D62:M62) -> 0.65322 | O62: =IF(C62="g",0.001,1) -> 1 | P62: =IF(OR(C62="kg",C62="KG",C62="l"),1,IF(C62="g",0.001,0)) -> 1
B63: POIDS TOTAL PÂTÉ (kg) | D63: =SUMPRODUCT(D9:D62,$P$9:$P$62) -> 10.482749 | E63: =SUMPRODUCT(E9:E62,$P$9:$P$62) -> 25.610579 | F63: =SUMPRODUCT(F9:F62,$P$9:$P$62) -> 0 | G63: =SUMPRODUCT(G9:G62,$P$9:$P$62) -> 22.188944 | H63: =SUMPRODUCT(H9:H62,$P$9:$P$62) -> 0 | I63: =SUMPRODUCT(I9:I62,$P$9:$P$62) -> 27.760385 | J63: =SUMPRODUCT(J9:J62,$P$9:$P$62) -> 0 | K63: =SUMPRODUCT(K9:K62,$P$9:$P$62) -> 0 | ... M63: =SUMPRODUCT(M9:M62,$P$9:$P$62) -> 22.243924 | N63: =SUM(D63:M63) -> 108.28658
B66: RÉPARTITION EN BOCAUX (saisir le nb de bocaux par format)
B67: Pâté | C67: 110 g | D67: 180 g | E67: 315 g | F67: 450 g | G67: 675 g | H67: Poids emballé (kg) | I67: Poids total (kg) | J67: Écart (kg) | K67: Nb 315g suggéré
B68: Pâté de lièvre | C68: 0 | D68: 0 | E68: 0 | F68: 0 | G68: 0 | H68: =C68*Paramètres!$I$11+D68*Paramètres!$I$12+E68*Paramètres!$I$13+F68*Paramètres!$I$14+G68*Paramètres!$I$15 -> 0 | I68: =D$63 -> 10.482749 | J68: =I68-H68 -> 10.482749 | K68: =ROUND(I68/Paramètres!$I$13,0) -> 33
B69: Pâté de chevreuil | C69: 0 | D69: 0 | E69: 0 | F69: 0 | G69: 0 | H69: =C69*Paramètres!$I$11+D69*Paramètres!$I$12+E69*Paramètres!$I$13+F69*Paramètres!$I$14+G69*Paramètres!$I$15 -> 0 | I69: =E$63 -> 25.610579 | J69: =I69-H69 -> 25.610579 | K69: =ROUND(I69/Paramètres!$I$13,0) -> 81
B70: Pâté de sanglier (campagne) | C70: 0 | D70: 0 | E70: 0 | F70: 0 | G70: 0 | H70: =C70*Paramètres!$I$11+D70*Paramètres!$I$12+E70*Paramètres!$I$13+F70*Paramètres!$I$14+G70*Paramètres!$I$15 -> 0 | I70: =F$63 -> 0 | J70: =I70-H70 -> 0 | K70: =ROUND(I70/Paramètres!$I$13,0) -> 0
B71: Pâté de faisan | C71: 0 | D71: 0 | E71: 0 | F71: 0 | G71: 0 | H71: =C71*Paramètres!$I$11+D71*Paramètres!$I$12+E71*Paramètres!$I$13+F71*Paramètres!$I$14+G71*Paramètres!$I$15 -> 0 | I71: =G$63 -> 22.188944 | J71: =I71-H71 -> 22.188944 | K71: =ROUND(I71/Paramètres!$I$13,0) -> 70
B72: Daube de sanglier | C72: 0 | D72: 0 | E72: 0 | F72: 0 | G72: 0 | H72: =C72*Paramètres!$I$11+D72*Paramètres!$I$12+E72*Paramètres!$I$13+F72*Paramètres!$I$14+G72*Paramètres!$I$15 -> 0 | I72: =H$63 -> 0 | J72: =I72-H72 -> 0 | K72: =ROUND(I72/Paramètres!$I$13,0) -> 0
B73: Pâté de foie de sanglier | C73: 0 | D73: 0 | E73: 0 | F73: 0 | G73: 0 | H73: =C73*Paramètres!$I$11+D73*Paramètres!$I$12+E73*Paramètres!$I$13+F73*Paramètres!$I$14+G73*Paramètres!$I$15 -> 0 | I73: =I$63 -> 27.760385 | J73: =I73-H73 -> 27.760385 | K73: =ROUND(I73/Paramètres!$I$13,0) -> 88
B74: Pâté de foie de chevreuil | C74: 0 | D74: 0 | E74: 0 | F74: 0 | G74: 0 | H74: =C74*Paramètres!$I$11+D74*Paramètres!$I$12+E74*Paramètres!$I$13+F74*Paramètres!$I$14+G74*Paramètres!$I$15 -> 0 | I74: =J$63 -> 0 | J74: =I74-H74 -> 0 | K74: =ROUND(I74/Paramètres!$I$13,0) -> 0
B75: Rillette de perdreaux | C75: 0 | D75: 0 | E75: 0 | F75: 0 | G75: 0 | H75: =C75*Paramètres!$I$11+D75*Paramètres!$I$12+E75*Paramètres!$I$13+F75*Paramètres!$I$14+G75*Paramètres!$I$15 -> 0 | I75: =K$63 -> 0 | J75: =I75-H75 -> 0 | K75: =ROUND(I75/Paramètres!$I$13,0) -> 0
B76: Rillette de lièvre | C76: 0 | D76: 0 | E76: 0 | F76: 0 | G76: 0 | H76: =C76*Paramètres!$I$11+D76*Paramètres!$I$12+E76*Paramètres!$I$13+F76*Paramètres!$I$14+G76*Paramètres!$I$15 -> 0 | I76: =L$63 -> 0 | J76: =I76-H76 -> 0 | K76: =ROUND(I76/Paramètres!$I$13,0) -> 0
B77: Civet de chevreuil | C77: 0 | D77: 0 | E77: 0 | F77: 0 | G77: 0 | H77: =C77*Paramètres!$I$11+D77*Paramètres!$I$12+E77*Paramètres!$I$13+F77*Paramètres!$I$14+G77*Paramètres!$I$15 -> 0 | I77: =M$63 -> 22.243924 | J77: =I77-H77 -> 22.243924 | K77: =ROUND(I77/Paramètres!$I$13,0) -> 71
B78: TOTAL | C78: =SUM(C68:C77) -> 0 | D78: =SUM(D68:D77) -> 0 | E78: =SUM(E68:E77) -> 0 | F78: =SUM(F68:F77) -> 0 | G78: =SUM(G68:G77) -> 0 | H78: =SUM(H68:H77) -> 0 | I78: =SUM(I68:I77) -> 108.28658 | J78: =SUM(J68:J77) -> 108.28658

Sheet Liste de courses
B2: LISTE DE COURSES — calculée automatiquement
B3: Légende : 🔵 bleu = à remplir vous-même ⚫ noir = calcul automatique. Survolez les triangles rouges pour l'aide.
B4: Besoin = Production. Saisissez « En stock » et « Qui ». À acheter et Coût se calculent.
B6: Ingrédient | C6: Unité | D6: Besoin | E6: En stock | F6: À acheter | G6: Prix unit. (€) | H6: Coût (€) | I6: Qui s'en occupe | J6: Statut
B7: =Paramètres!B23 -> gorge de porc | C7: =Paramètres!C23 -> kg | D7: =Production!N21 -> 21.95504 | E7: 0 | F7: =MAX(D7-E7,0) -> 21.95504 | G7: =Paramètres!D23 -> 3.2 | H7: =F7*G7*IF(C7="g",0.001,1) -> 70.256128 | J7: À faire
B8: =Paramètres!B24 -> ECHINE DE PORC | C8: =Paramètres!C24 -> kg | D8: =Production!N22 -> 0 | E8: 0 | F8: =MAX(D8-E8,0) -> 0 | G8: =Paramètres!D24 -> 8 | H8: =F8*G8*IF(C8="g",0.001,1) -> 0 | J8: À faire
B9: =Paramètres!B25 -> lard GRAS | C9: =Paramètres!C25 -> kg | D9: =Production!N23 -> 0 | E9: 0 | F9: =MAX(D9-E9,0) -> 0 | G9: =Paramètres!D25 -> 12 | H9: =F9*G9*IF(C9="g",0.001,1) -> 0 | J9: À faire
B10: =Paramètres!B26 -> poitrine de porc | C10: =Paramètres!C26 -> kg | D10: =Production!N24 -> 3.2422 | E10: 0 | F10: =MAX(D10-E10,0) -> 3.2422 | G10: =Paramètres!D26 -> 8 | H10: =F10*G10*IF(C10="g",0.001,1) -> 25.9376 | J10: À faire
B11: =Paramètres!B27 -> poitrine fumée | C11: =Paramètres!C27 -> kg | D11: =Production!N25 -> 0 | E11: 0 | F11: =MAX(D11-E11,0) -> 0 | G11: =Paramètres!D27 -> 12.5 | H11: =F11*G11*IF(C11="g",0.001,1) -> 0 | J11: À faire
B12: =Paramètres!B28 -> chair à saucisse | C12: =Paramètres!C28 -> kg | D12: =Production!N26 -> 0 | E12: 0 | F12: =MAX(D12-E12,0) -> 0 | G12: =Paramètres!D28 -> 10 | H12: =F12*G12*IF(C12="g",0.001,1) -> 0 | J12: À faire
B13: =Paramètres!B29 -> barde | C13: =Paramètres!C29 -> m2 | D13: =Production!N27 -> 0 | E13: 0 | F13: =MAX(D13-E13,0) -> 0 | G13: =Paramètres!D29 -> 20 | H13: =F13*G13*IF(C13="g",0.001,1) -> 0 | J13: À faire
B14: =Paramètres!B30 -> VEAU poitrine | C14: =Paramètres!C30 -> kg | D14: =Production!N28 -> 3.4257 | E14: 0 | F14: =MAX(D14-E14,0) -> 3.4257 | G14: =Paramètres!D30 -> 16 | H14: =F14*G14*IF(C14="g",0.001,1) -> 54.8112 | J14: À faire
B15: =Paramètres!B31 -> foie de volailles | C15: =Paramètres!C31 -> kg | D15: =Production!N29 -> 0 | E15: 0 | F15: =MAX(D15-E15,0) -> 0 | G15: =Paramètres!D31 -> 15 | H15: =F15*G15*IF(C15="g",0.001,1) -> 0 | J15: À faire
B16: =Paramètres!B32 -> saindoux | C16: =Paramètres!C32 -> kg | D16: =Production!N30 -> 0 | E16: 0 | F16: =MAX(D16-E16,0) -> 0 | G16: =Paramètres!D32 -> 6 | H16: =F16*G16*IF(C16="g",0.001,1) -> 0 | J16: À faire
B17: =Paramètres!B33 -> sel | C17: =Paramètres!C33 -> kg | D17: =Production!N31 -> 0.5903892 | E17: 0 | F17: =MAX(D17-E17,0) -> 0.5903892 | G17: =Paramètres!D33 -> 1.2 | H17: =F17*G17*IF(C17="g",0.001,1) -> 0.70846704 | J17: À faire
B18: =Paramètres!B34 -> poivre | C18: =Paramètres!C34 -> kg | D18: =Production!N32 -> 0.0983982 | E18: 0 | F18: =MAX(D18-E18,0) -> 0.0983982 | G18: =Paramètres!D34 -> 30 | H18: =F18*G18*IF(C18="g",0.001,1) -> 2.951946 | J18: À faire
... B48: =Paramètres!B64 -> porto | C48: =Paramètres!C64 -> l | D48: =Production!N62 -> 0.65322 | E48: 0 | F48: =MAX(D48-E48,0) -> 0.65322 | G48: =Paramètres!D64 -> 25 | H48: =F48*G48*IF(C48="g",0.001,1) -> 16.3305 | J48: À faire
B49: TOTAL ACHATS (€) | H49: =SUM(H7:H48) -> 345.772
B51: BOCAUX À PRÉVOIR
B52: Format | C52: En stock | D52: Prévu (Production) | E52: À acheter
B53: 110 g | C53: 5 | D53: =Production!C78 -> 0 | E53: =MAX(D53-C53,0) -> 0
B54: 180 g | C54: 54 | D54: =Production!D78 -> 0 | E54: =MAX(D54-C54,0) -> 0
B55: 315 g | C55: 118 | D55: =Production!E78 -> 0 | E55: =MAX(D55-C55,0) -> 0
B56: 450 g | C56: 21 | D56: =Production!F78 -> 0 | E56: =MAX(D56-C56,0) -> 0
B57: 675 g | C57: 13 | D57: =Production!G78 -> 0 | E57: =MAX(D57-C57,0) -> 0

Sheet Budget & Comptes
B2: BUDGET & COMPTES
B3: Légende : 🔵 bleu = à remplir vous-même ⚫ noir = calcul automatique. Survolez les triangles rouges pour l'aide.
B4: BUDGET PRÉVISIONNEL (estimé d'après les recettes)
B5: Coût total des ingrédients (€) | C5: =SUMPRODUCT(Production!N9:N62,Paramètres!D11:D64,Production!O9:O62) -> 345.772
B6: Nombre de participants | C6: =Paramètres!C7 -> 7
B7: Coût estimé par participant (€) | C7: =IFERROR(C5/C6,0) -> 49.396001
B9: COÛT ESTIMÉ PAR PÂTÉ
B10: Pâté | C10: Coût (€)
B11: Pâté de lièvre | C11: =SUMPRODUCT(Production!D9:D62,Paramètres!$D$11:$D$64,Production!$O$9:$O$62) -> 26.130738
B12: Pâté de chevreuil | C12: =SUMPRODUCT(Production!E9:E62,Paramètres!$D$11:$D$64,Production!$O$9:$O$62) -> 73.239026
B13: Pâté de sanglier (campagne) | C13: =SUMPRODUCT(Production!F9:F62,Paramètres!$D$11:$D$64,Production!$O$9:$O$62) -> 0
B14: Pâté de faisan | C14: =SUMPRODUCT(Production!G9:G62,Paramètres!$D$11:$D$64,Production!$O$9:$O$62) -> 101.81729
B15: Daube de sanglier | C15: =SUMPRODUCT(Production!H9:H62,Paramètres!$D$11:$D$64,Production!$O$9:$O$62) -> 0
B16: Pâté de foie de sanglier | C16: =SUMPRODUCT(Production!I9:I62,Paramètres!$D$11:$D$64,Production!$O$9:$O$62) -> 49.62578
B17: Pâté de foie de chevreuil | C17: =SUMPRODUCT(Production!J9:J62,Paramètres!$D$11:$D$64,Production!$O$9:$O$62) -> 0
B18: Rillette de perdreaux | C18: =SUMPRODUCT(Production!K9:K62,Paramètres!$D$11:$D$64,Production!$O$9:$O$62) -> 0
B19: Rillette de lièvre | C19: =SUMPRODUCT(Production!L9:L62,Paramètres!$D$11:$D$64,Production!$O$9:$O$62) -> 0
B20: Civet de chevreuil | C20: =SUMPRODUCT(Production!M9:M62,Paramètres!$D$11:$D$64,Production!$O$9:$O$62) -> 94.959175
B21: TOTAL | C21: =SUM(C11:C20) -> 345.772
B24: COMPTES RÉELS DE LA JOURNÉE 2026
B25: Qui | C25: Poste | D25: Montant (€)
B26: benoit | C26: achat bocaux | D26: 182.28
B27: vincent | C27: foie de volaille et mirabelle | D27: 34.24
B28: thomas | C28: étiquettes | D28: 10
B29: fred | C29: petit complément du jour J (Intermarché) | D29: 17.08
B30: fred | C30: gorge de porc (Pruvost Leroy) | D30: 103.22
B31: fred | C31: joints (Gamm Vert) | D31: 42.73
B32: fred | C32: vins, armagnac, épices, veau (Intermarché) | D32: 140.19
B38: TOTAL DÉPENSES | D38: =SUM(D26:D37) -> 529.74
B39: Part par participant (€) | D39: =IFERROR(D38/Paramètres!C7,0) -> 75.677143
B41: REMBOURSEMENTS
B42: Qui | C42: Montant (€) | D42: À
B43: olivier | C43: 75.68 | D43: benoit
B44: jb | C44: 75.68 | D44: fred
B45: antoine | C45: 75.68 | D45: fred
B46: denis | C46: 75.68 | D46: fred
B47: vincent | C47: 30.92 | D47: benoit
B48: (à régler) | C48: 10 | D48: thomas
